2022-07-15 23:16:45,288 ERROR [/Users/aokihirotaka/Pictures/udemy/ClassBaseView/class_based_view/class_based_view/middleware.py:16] この名前は使用できません
Traceback (most recent call last):
  File "/Users/aokihirotaka/opt/anaconda3/envs/djangoenv/lib/python3.8/site-packages/django/core/handlers/base.py", line 197, in _get_response
    response = wrapped_callback(request, *callback_args, **callback_kwargs)
  File "/Users/aokihirotaka/opt/anaconda3/envs/djangoenv/lib/python3.8/site-packages/django/views/generic/base.py", line 84, in view
    return self.dispatch(request, *args, **kwargs)
  File "/Users/aokihirotaka/opt/anaconda3/envs/djangoenv/lib/python3.8/site-packages/django/views/generic/base.py", line 119, in dispatch
    return handler(request, *args, **kwargs)
  File "/Users/aokihirotaka/opt/anaconda3/envs/djangoenv/lib/python3.8/site-packages/django/views/generic/base.py", line 185, in get
    context = self.get_context_data(**kwargs)
  File "/Users/aokihirotaka/Pictures/udemy/ClassBaseView/class_based_view/store/views.py", line 62, in get_context_data
    raise Http404('この名前は使用できません')
django.http.response.Http404: この名前は使用できません
